<?xml version='1.0'?>


<robot name="my_robot" xmlns:xacro="http://www.ros.org/wiki/xacro">
    
    <xacro:include filename="$(find my_robot)/urdf/MSE6.gazebo" />

    <link name="robot_footprint"></link>

    <joint name="robot_footprint_joint" type="fixed">
        <origin xyz="0 0 0" rpy="0 0 0" />
        <parent link="robot_footprint"/>
	    <child link="chassis"/>
    </joint>

    <link name="chassis">
        <pose>0 0 0 0 0 0</pose>

        <inertial>
            <mass value="3.0"/>
            <origin xyz="0 0 .01" rpy="0 0 0"/>
            <inertia
                ixx="0.0067" ixy="0" ixz="0"
                iyy="0.0267" iyz="0"
                izz="0.025"
                />
        </inertial>

        <collision name="collision">
            <origin xyz="0 0 .01" rpy="0 0 0"/>
            <geometry>
               <box size=".30 .1 .13"/> 
            </geometry>
        </collision>

        <visual name="chassis_visual">
            <origin xyz="0 0 -.05" rpy="0 0 0 "/>
            <geometry>
                <mesh filename="package://my_robot/meshes/MS6E.dae"/>
            </geometry>
        </visual>

    </link>

    <link name="front_right_strut">
        <collision>
            <origin xyz="0 0 0" rpy="0 0 0"/>
            <geometry>
                <box size="0.01 0.005 0.015"/>
            </geometry>
        </collision>

        <inertial>
            <origin xyz="0 0 0" rpy="0 0 0"/>
            <mass value="1e-5"/>
            <inertia 
                ixx="1e-6" ixy="0" ixz="0"
                iyy="1e-6" iyz="0"
                izz="1e-6"
                />
        </inertial>

        <visual>
            <origin xyz="0 0 0" rpy="0 0 0"/>
            <geometry>
               <box size="0.01 0.005 0.015"/>
            </geometry>
        </visual>

    </link>


    <link name="front_right_wheel">

        <collision>
            <origin xyz="0 0 0" rpy="0 1.5707 1.5707"/>
            <geometry>
                <cylinder radius="0.025" length="0.015"/>
            </geometry>
        </collision>
        
        <inertial>
            <mass value=".1"/>
            <origin xyz="0 0 0" rpy="0 1.5707 1.5707"/>
            <inertia
            ixx="0.000018" ixy="0" ixz="0"
            iyy="0.000018" iyz="0"
            izz="0.000031" 
            />
        </inertial>

        <visual>
            <origin xyz="0 0 0" rpy="0 1.5707 1.5707"/>
            <geometry>
                <cylinder radius="0.025" length="0.015"/>
            </geometry>
        </visual>
    
    </link>

    <link name="rear_right_strut">
        <collision>
            <origin xyz="0 0 0" rpy="0 0 0"/>
            <geometry>
                <box size="0.01 0.01 0.025"/>
            </geometry>
        </collision>

        <inertial>
            <origin xyz="0 0 0" rpy="0 0 0"/>
            <mass value="1e-5"/>
            <inertia 
                ixx="1e-6" ixy="0" ixz="0"
                iyy="1e-6" iyz="0"
                izz="1e-6"
                />
        </inertial>

        <visual>
            <origin xyz="0 0 0" rpy="0 0 0"/>
            <geometry>
               <box size="0.01 0.01 0.025"/>
            </geometry>
        </visual>

    </link>

    <link name="rear_right_wheel">

        <collision>
            <origin xyz="0 0 0" rpy="0 1.5707 1.5707"/>
            <geometry>
                <cylinder radius="0.030" length="0.015"/>
            </geometry>
        </collision>
        
        <inertial>
            <mass value=".1"/>
            <origin xyz="0 0 0" rpy="0 1.5707 1.5707"/>
            <inertia
               ixx="0.000024" ixy="0" ixz="0"
               iyy="0.000024" iyz="0"
               izz="0.000045" 
            />
        </inertial>

        <visual>
            <origin xyz="0 0 0" rpy="0 1.5707 1.5707"/>
            <geometry>
                <cylinder radius="0.030" length="0.015"/>
            </geometry>
        </visual>
    
    </link>


    <link name="front_left_strut">
        <collision>
            <origin xyz="0 0 0" rpy="0 0 0"/>
            <geometry>
                <box size="0.01 0.005 0.015"/>
            </geometry>
        </collision>

        <inertial>
            <origin xyz="0 0 0" rpy="0 0 0"/>
            <mass value="1e-5"/>
            <inertia 
                ixx="1e-6" ixy="0" ixz="0"
                iyy="1e-6" iyz="0"
                izz="1e-6"
                />
        </inertial>

        <visual>
            <origin xyz="0 0 0" rpy="0 0 0"/>
            <geometry>
               <box size="0.01 0.005 0.015"/>
            </geometry>
        </visual>

    </link>

    <link name="front_left_wheel">

        <collision>
            <origin xyz="0 0 0" rpy="0 1.5707 1.5707"/>
            <geometry>
                <cylinder radius="0.025" length="0.015"/>
            </geometry>
        </collision>
        
        <inertial>
            <mass value=".1"/>
            <origin xyz="0 0 0" rpy="0 1.5707 1.5707"/>
            <inertia
               ixx="0.000018" ixy="0" ixz="0"
               iyy="0.000018" iyz="0"
               izz="0.000031" 
            />
        </inertial>

        <visual>
            <origin xyz="0 0 0" rpy="0 1.5707 1.5707"/>
            <geometry>
                <cylinder radius="0.025" length="0.015"/>
            </geometry>
        </visual>

     </link>

    <link name="rear_left_strut">
        <collision>
            <origin xyz="0 0 0" rpy="0 0 0"/>
            <geometry>
                <box size="0.01 0.01 0.025"/>
            </geometry>
        </collision>

        <inertial>
            <origin xyz="0 0 0" rpy="0 0 0"/>
            <mass value="1e-5"/>
            <inertia 
                ixx="1e-6" ixy="0" ixz="0"
                iyy="1e-6" iyz="0"
                izz="1e-6"
                />
        </inertial>

        <visual>
            <origin xyz="0 0 0" rpy="0 0 0"/>
            <geometry>
               <box size="0.01 0.01 0.025"/>
            </geometry>
        </visual>

    </link>

    <link name="rear_left_wheel">
        <collision>
            <origin xyz="0 0 0" rpy="0 1.5707 1.5707"/>
            <geometry>
                <cylinder radius="0.030" length="0.015"/>
            </geometry>
        </collision>
        
        <inertial>
            <mass value=".1"/>
            <origin xyz="0 0 0" rpy="0 1.5707 1.5707"/>
            <inertia
               ixx="0.000024" ixy="0" ixz="0"
               iyy="0.000024" iyz="0"
               izz="0.000045" 
            />
        </inertial>

        <visual>
            <origin xyz="0 0 0" rpy="0 1.5707 1.5707"/>
            <geometry>
                <cylinder radius="0.030" length="0.015"/>
            </geometry>
        </visual>
    
    </link>
        <gazebo reference="front_left_wheel">
            <material>Gazebo/Black</material>
        </gazebo>
        
        <gazebo reference="front_right_wheel">
            <material>Gazebo/Black</material>
        </gazebo>
        
        <gazebo reference="rear_left_wheel">
            <material>Gazebo/Black</material>
        </gazebo>
        
        <gazebo reference="rear_right_wheel">
            <material>Gazebo/Black</material>
        </gazebo>
        
        <gazebo reference="chassis">
            <material>Gazebo/Road</material>
        </gazebo>

        <gazebo reference="camera">
            <material>Gazebo/Blue</material>
        </gazebo>

    <joint name="front_left_steer_bearing" type="revolute">
        <origin xyz="0.09 0.057 -.079" rpy="0 0 0"/>
        <child link="front_left_strut"/>
        <parent link="chassis"/>
        <axis xyz="0 0 1" rpy="0 0 0"/>
        <limit effort="50" velocity="1.0" lower="-0.3" upper="0.3"/>
    </joint>

    <joint name="front_left_wheel_bearing" type="continuous">
        <origin xyz="0 .011 0.01" rpy="0 0 0"/>
        <child link="front_left_wheel"/>
        <parent link="front_left_strut"/>
        <axis xyz="0 1 0" rpy="0 0 0"/>
        <limit effort="100" velocity="100"/>
    </joint>

    <joint name="front_right_steer_bearing" type="revolute">
        <origin xyz="0.09 -0.057 -.079" rpy="0 0 0"/>
        <child link="front_right_strut"/>
        <parent link="chassis"/>
        <axis xyz="0 0 1" rpy="0 0 0"/>
        <limit effort="50" velocity="1.0" lower="-0.3" upper="0.3"/>
    </joint>

    <joint name="front_right_wheel_bearing" type="continuous">
        <origin xyz="0 -.011 0.01" rpy="0 0 0"/>
        <child link="front_right_wheel"/>
        <parent link="front_right_strut"/>
        <axis xyz="0 1 0" rpy="0 0 0"/>
        <limit effort="100" velocity="100"/>
    </joint>

    <joint name="rear_left_steer_bearing" type="fixed">
        <origin xyz="-0.09 0.067 -.053" rpy="0 0 0"/>
        <child link="rear_left_strut"/>
        <parent link="chassis"/>
        <axis xyz="0 0 1" rpy="0 0 0"/>
        <limit effort="100" velocity="100"/>
        <dynamics damping=".0" friction=".00"/>
    </joint>

    <joint name="rear_left_wheel_bearing" type="continuous">
        <origin xyz="0 0 0" rpy="0 0 0"/>
        <child link="rear_left_wheel"/>
        <parent link="rear_left_strut"/>
        <axis xyz="0 1 0" rpy="0 0 0"/>
        <limit effort="100" velocity="100"/>
        <dynamics damping=".0" friction=".00"/>
    </joint>
        
    <joint name="rear_right_steer_bearing" type="fixed">
        <origin xyz="-0.09 -0.067 -.053" rpy="0 0 0"/>
        <child link="rear_right_strut"/>
        <parent link="chassis"/>
        <axis xyz="0 0 1" rpy="0 0 0"/>
        <limit effort="100" velocity="100"/>
        <dynamics damping=".0" friction=".00"/>
    </joint>

    <joint name="rear_right_wheel_bearing" type="continuous">
        <origin xyz="0 0 0" rpy="0 0 0"/>
        <child link="rear_right_wheel"/>
        <parent link="rear_right_strut"/>
        <axis xyz="0 1 0" rpy="0 0 0"/>
        <limit effort="100" velocity="100"/>
        <dynamics damping=".0" friction=".00"/>
    </joint>
        
    <link name="camera">
        <collision>
            <origin xyz="0 0 0" rpy="0 0 0"/>
            <geometry>
                <sphere radius="0.02"/>
            </geometry>
        </collision>

        <inertial>
            <origin xyz="0 0 0" rpy="0 0 0"/>
            <mass value="0.1"/>
            <inertia
                ixx="1e-6" ixy="0" ixz="0"
                iyy="1e-6" iyz="0"
                izz="1e-6"
                />
        </inertial>

        <visual>
            <origin xyz="0 0 0" rpy="0 0 0"/>
            <geometry>
                <sphere radius="0.02"/>
            </geometry>
        </visual>

    </link>

    <joint name="camera_joint" type="fixed">
        <origin xyz="0.14 0 0.02" rpy="0 0 0"/>
        <parent link="chassis"/>
        <child link="camera"/>
        <axis xyz="0 1 0"/>
    </joint>

    <link name="hokuyo">
        <collision>
            <origin xyz="0 0 0" rpy="0 0 0"/>
            <geometry>
                <box size="0.1 0.1 0.1"/>
            </geometry>
        </collision>

        <inertial>
            <origin xyz="0 0 0" rpy="0 0 0"/>
            <mass value="1e-5"/>
            <inertia 
                ixx="1e-6" ixy="0" ixz="0"
                iyy="1e-6" iyz="0"
                izz="1e-6"
                />
        </inertial>

        <visual>
            <origin xyz="0 0 0" rpy="0 0 0"/>
            <geometry>
                <mesh filename="package://my_robot/meshes/hokuyo.dae"/>
            </geometry>
        </visual>

    </link>

    <joint name="hokuyo_joint" type="fixed">
        <origin xyz="0.03 0 .14" rpy="0 0 0"/>
        <axis xyz="0 1 0"/>
        <parent link="chassis"/>
        <child link="hokuyo"/>
    </joint>






</robot>



